<?xml version="1.0" ?>
<!-- =================================================================================== -->
<!-- |    This document was autogenerated by xacro from /home/dada/raicam_ws/summit_arm_sim/src/husky_isaac_sim/urdf/husky_ur5.urdf.xacro | -->
<!-- |    EDITING THIS FILE BY HAND IS NOT RECOMMENDED                                 | -->
<!-- =================================================================================== -->
<robot name="husky_ur5">
  <!-- ################################################### husky ########################################################################## -->
  <material name="dark_grey">
    <color rgba="0.2 0.2 0.2 1.0"/>
  </material>
  <material name="medium_grey">
    <color rgba="0.6 0.6 0.6 1.0"/>
  </material>
  <material name="light_grey">
    <color rgba="0.8 0.8 0.8 1.0"/>
  </material>
  <material name="yellow">
    <color rgba="0.8 0.8 0.0 1.0"/>
  </material>
  <material name="black">
    <color rgba="0.15 0.15 0.15 1.0"/>
  </material>
  <material name="white">
    <color rgba="1.0 1.0 1.0 1.0"/>
  </material>
  <material name="red">
    <color rgba="1.0 0.0 0.0 1.0"/>
  </material>
  <!-- Includes -->
  <material name="zed_mat">
    <color rgba="0.8 0.8 0.8 0.8"/>
  </material>
  <material name="zedm_mat">
    <color rgba="0 0 0 0.9"/>
  </material>
  <material name="zed2_mat">
    <color rgba="0.25 0.25 0.25 0.99"/>
  </material>
  <!-- Base link is the center of the robot's bottom plate -->
  <link name="husky_base_link">
    <visual>
      <origin rpy="0 0 0" xyz="0 0 0"/>
      <geometry>
        <mesh filename="file:///home/dada/raicam_ws/summit_arm_sim/src/husky_description/meshes/base_link.dae"/>
      </geometry>
    </visual>
    <collision>
      <origin rpy="0 0 0" xyz="0.0 0 0.061875"/>
      <geometry>
        <box size="0.9874 0.5709 0.12375"/>
      </geometry>
    </collision>
    <collision>
      <origin rpy="0 0 0" xyz="0 0 0.17562499999999998"/>
      <geometry>
        <box size="0.7899200000000001 0.5709 0.10375"/>
      </geometry>
    </collision>
  </link>
  <!-- Base footprint is on the ground under the robot -->
  <!--<link name="${prefix}base_footprint"/>

    <joint name="${prefix}base_footprint_joint" type="fixed">
      <origin xyz="0 0 ${wheel_vertical_offset - wheel_radius}" rpy="0 0 0" />
      <parent link="${prefix}base_link" />
      <child link="${prefix}base_footprint" />
    </joint>-->
  <!-- Inertial link stores the robot's inertial information -->
  <link name="husky_inertial_link">
    <inertial>
      <mass value="46.034"/>
      <origin xyz="-0.00065 -0.085 0.062"/>
      <inertia ixx="0.6022" ixy="-0.02364" ixz="-0.1197" iyy="1.7386" iyz="-0.001544" izz="2.0296"/>
    </inertial>
  </link>
  <joint name="husky_inertial_joint" type="fixed">
    <origin rpy="0 0 0" xyz="0 0 0"/>
    <parent link="husky_base_link"/>
    <child link="husky_inertial_link"/>
  </joint>
  <!-- IMU Link-->
  <!-- Can be modified with environment variables in /etc/ros/setup.bash -->
  <!--<link name="${prefix}imu_link"/>
    <joint name="${prefix}imu_joint" type="fixed">
      <origin xyz="$(optenv CPR_IMU_XYZ 0 0 0)" rpy="$(optenv CPR_IMU_RPY 0 0 0)" />
      <parent link="${prefix}base_link" />
      <child link="${prefix}imu_link" />
    </joint>-->
  <!-- GPS Link-->
  <!-- Can be modified with environment variables in /etc/ros/setup.bash -->
  <!--<link name="${prefix}gps_link"/>
    <joint name="${prefix}gps_joint" type="fixed">
      <origin xyz="$(optenv CPR_GPS_XYZ 0 0 0)" rpy="$(optenv CPR_GPS_RPY 0 0 0)" />
      <parent link="${prefix}base_link" />
      <child link="${prefix}gps_link" />
    </joint>-->
  <link name="husky_front_left_wheel">
    <inertial>
      <mass value="2.637"/>
      <origin xyz="0 0 0"/>
      <inertia ixx="0.02467" ixy="0" ixz="0" iyy="0.04411" iyz="0" izz="0.02467"/>
    </inertial>
    <visual>
      <origin rpy="0 0 0" xyz="0 0 0"/>
      <geometry>
        <mesh filename="file:///home/dada/raicam_ws/summit_arm_sim/src/husky_description/meshes/wheel.dae"/>
      </geometry>
    </visual>
    <collision>
      <origin rpy="1.570795 0 0" xyz="0 0 0"/>
      <geometry>
        <cylinder length="0.1143" radius="0.1651"/>
      </geometry>
    </collision>
  </link>
  <joint name="husky_front_left_wheel_joint" type="continuous">
    <parent link="husky_base_link"/>
    <child link="husky_front_left_wheel"/>
    <origin rpy="0 0 0" xyz="0.256 0.2854 0.03282"/>
    <axis rpy="0 0 0" xyz="0 1 0"/>
  </joint>
  <link name="husky_front_right_wheel">
    <inertial>
      <mass value="2.637"/>
      <origin xyz="0 0 0"/>
      <inertia ixx="0.02467" ixy="0" ixz="0" iyy="0.04411" iyz="0" izz="0.02467"/>
    </inertial>
    <visual>
      <origin rpy="0 0 0" xyz="0 0 0"/>
      <geometry>
        <mesh filename="file:///home/dada/raicam_ws/summit_arm_sim/src/husky_description/meshes/wheel.dae"/>
      </geometry>
    </visual>
    <collision>
      <origin rpy="1.570795 0 0" xyz="0 0 0"/>
      <geometry>
        <cylinder length="0.1143" radius="0.1651"/>
      </geometry>
    </collision>
  </link>
  <joint name="husky_front_right_wheel_joint" type="continuous">
    <parent link="husky_base_link"/>
    <child link="husky_front_right_wheel"/>
    <origin rpy="0 0 0" xyz="0.256 -0.2854 0.03282"/>
    <axis rpy="0 0 0" xyz="0 1 0"/>
  </joint>
  <link name="husky_rear_left_wheel">
    <inertial>
      <mass value="2.637"/>
      <origin xyz="0 0 0"/>
      <inertia ixx="0.02467" ixy="0" ixz="0" iyy="0.04411" iyz="0" izz="0.02467"/>
    </inertial>
    <visual>
      <origin rpy="0 0 0" xyz="0 0 0"/>
      <geometry>
        <mesh filename="file:///home/dada/raicam_ws/summit_arm_sim/src/husky_description/meshes/wheel.dae"/>
      </geometry>
    </visual>
    <collision>
      <origin rpy="1.570795 0 0" xyz="0 0 0"/>
      <geometry>
        <cylinder length="0.1143" radius="0.1651"/>
      </geometry>
    </collision>
  </link>
  <joint name="husky_rear_left_wheel_joint" type="continuous">
    <parent link="husky_base_link"/>
    <child link="husky_rear_left_wheel"/>
    <origin rpy="0 0 0" xyz="-0.256 0.2854 0.03282"/>
    <axis rpy="0 0 0" xyz="0 1 0"/>
  </joint>
  <link name="husky_rear_right_wheel">
    <inertial>
      <mass value="2.637"/>
      <origin xyz="0 0 0"/>
      <inertia ixx="0.02467" ixy="0" ixz="0" iyy="0.04411" iyz="0" izz="0.02467"/>
    </inertial>
    <visual>
      <origin rpy="0 0 0" xyz="0 0 0"/>
      <geometry>
        <mesh filename="file:///home/dada/raicam_ws/summit_arm_sim/src/husky_description/meshes/wheel.dae"/>
      </geometry>
    </visual>
    <collision>
      <origin rpy="1.570795 0 0" xyz="0 0 0"/>
      <geometry>
        <cylinder length="0.1143" radius="0.1651"/>
      </geometry>
    </collision>
  </link>
  <joint name="husky_rear_right_wheel_joint" type="continuous">
    <parent link="husky_base_link"/>
    <child link="husky_rear_right_wheel"/>
    <origin rpy="0 0 0" xyz="-0.256 -0.2854 0.03282"/>
    <axis rpy="0 0 0" xyz="0 1 0"/>
  </joint>
  <!-- <xacro:husky_wheel prefix="${prefix}" wheel_prefix="${prefix}front_left" path_meshes="${path_meshes}"
     x="${wheelbase/2}" y="${track/2}" z="${wheel_vertical_offset}"/>

    <joint name="husky_front_left_wheel_joint" type="fixed">
      <origin xyz="0 0 0" rpy="0 0 0" />
      <parent link="husky_base_link"/>
      <child link="husky_front_left_wheel"/>
    </joint> -->
  <!-- Spawn Husky chassis -->
  <link name="husky_top_chassis_link">
    <visual>
      <origin rpy="0 0 0" xyz="0 0 0"/>
      <geometry>
        <mesh filename="file:///home/dada/raicam_ws/summit_arm_sim/src/husky_description/meshes/top_chassis.dae"/>
      </geometry>
    </visual>
    <inertial>
      <mass value="0.01"/>
      <origin rpy="0 0 0" xyz="0 0 0"/>
      <inertia ixx="1.6666666666666668e-07" ixy="0" ixz="0" iyy="1.6666666666666668e-07" iyz="0" izz="1.6666666666666668e-07"/>
    </inertial>
  </link>
  <!-- Attach chassis to the robot -->
  <joint name="husky_top_chassis_joint" type="fixed">
    <parent link="husky_base_link"/>
    <child link="husky_top_chassis_link"/>
  </joint>
  <!-- Spawn user rails -->
  <link name="husky_user_rail_link">
    <visual>
      <geometry>
        <mesh filename="file:///home/dada/raicam_ws/summit_arm_sim/src/husky_description/meshes/user_rail.dae"/>
      </geometry>
    </visual>
    <inertial>
      <mass value="0.01"/>
      <origin rpy="0 0 0" xyz="0 0 0"/>
      <inertia ixx="1.6666666666666668e-07" ixy="0" ixz="0" iyy="1.6666666666666668e-07" iyz="0" izz="1.6666666666666668e-07"/>
    </inertial>
  </link>
  <!-- Attach user rails to base link -->
  <joint name="husky_user_rail" type="fixed">
    <origin rpy="0 0 0" xyz="0.272 0 0.245"/>
    <parent link="husky_base_link"/>
    <child link="husky_user_rail_link"/>
  </joint>
  <!-- Spawn front bumper link -->
  <link name="husky_front_bumper_link">
    <visual>
      <geometry>
        <mesh filename="file:///home/dada/raicam_ws/summit_arm_sim/src/husky_description/meshes/bumper.dae"/>
      </geometry>
    </visual>
    <inertial>
      <mass value="0.01"/>
      <origin rpy="0 0 0" xyz="0 0 0"/>
      <inertia ixx="1.6666666666666668e-07" ixy="0" ixz="0" iyy="1.6666666666666668e-07" iyz="0" izz="1.6666666666666668e-07"/>
    </inertial>
  </link>
  <!-- Attach front bumper -->
  <joint name="husky_front_bumper" type="fixed">
    <origin rpy="0 0 0" xyz="0.48 0 0.091"/>
    <parent link="husky_base_link"/>
    <child link="husky_front_bumper_link"/>
  </joint>
  <!-- Spawn rear bumper link -->
  <link name="husky_rear_bumper_link">
    <visual>
      <geometry>
        <mesh filename="file:///home/dada/raicam_ws/summit_arm_sim/src/husky_description/meshes/bumper.dae"/>
      </geometry>
    </visual>
    <inertial>
      <mass value="0.01"/>
      <origin rpy="0 0 0" xyz="0 0 0"/>
      <inertia ixx="1.6666666666666668e-07" ixy="0" ixz="0" iyy="1.6666666666666668e-07" iyz="0" izz="1.6666666666666668e-07"/>
    </inertial>
  </link>
  <!-- Attach rear bumper -->
  <joint name="husky_rear_bumper" type="fixed">
    <origin rpy="0 0 3.14159" xyz="-0.48 0 0.091"/>
    <parent link="husky_base_link"/>
    <child link="husky_rear_bumper_link"/>
  </joint>
  <link name="husky_top_plate_link">
    <visual>
      <origin rpy="0 0 0" xyz="0 0 0"/>
      <geometry>
        <mesh filename="file:///home/dada/raicam_ws/summit_arm_sim/src/husky_description/meshes/top_plate.dae"/>
      </geometry>
    </visual>
    <collision>
      <origin rpy="0 0 0" xyz="0 0 0"/>
      <geometry>
        <mesh filename="file:///home/dada/raicam_ws/summit_arm_sim/src/husky_description/meshes/top_plate.stl"/>
      </geometry>
    </collision>
  </link>
  <!-- Attach top plate -->
  <joint name="husky_top_plate_joint" type="fixed">
    <parent link="husky_base_link"/>
    <child link="husky_top_plate_link"/>
    <origin rpy="0 0 0" xyz="0.0812 0 0.245"/>
  </joint>
  <!-- Top plate front link -->
  <joint name="husky_top_plate_front_joint" type="fixed">
    <parent link="husky_top_plate_link"/>
    <child link="husky_top_plate_front_link"/>
    <origin rpy="0 0 0" xyz="0.36367 0 0.00639"/>
  </joint>
  <!-- Top plate rear link-->
  <joint name="husky_top_plate_rear_joint" type="fixed">
    <parent link="husky_top_plate_link"/>
    <child link="husky_top_plate_rear_link"/>
    <origin rpy="0 0 0" xyz="-0.36633 0 0.00639"/>
  </joint>
  <link name="husky_top_plate_front_link">
    <inertial>
      <mass value="0.01"/>
      <origin rpy="0 0 0" xyz="0 0 0"/>
      <inertia ixx="1.6666666666666668e-07" ixy="0" ixz="0" iyy="1.6666666666666668e-07" iyz="0" izz="1.6666666666666668e-07"/>
    </inertial>
  </link>
  <link name="husky_top_plate_rear_link">
    <inertial>
      <mass value="0.01"/>
      <origin rpy="0 0 0" xyz="0 0 0"/>
      <inertia ixx="1.6666666666666668e-07" ixy="0" ixz="0" iyy="1.6666666666666668e-07" iyz="0" izz="1.6666666666666668e-07"/>
    </inertial>
  </link>
  <!-- <xacro:if value="$(arg laser_enabled)">

      <xacro:sick_lms1xx_mount prefix="base"/>

      <xacro:sick_lms1xx frame="base_laser" topic="scan" robot_namespace="$(arg robot_namespace)"/>

      <joint name="laser_mount_joint" type="fixed">
        <origin xyz="$(arg laser_xyz)" rpy="$(arg laser_rpy)" />
        <parent link="top_plate_link" />
        <child link="base_laser_mount" />
      </joint>

    </xacro:if> -->
  <!-- Spawn the sensor arch link -->
  <link name="husky_sensor_arch_mount_link">
    <origin rpy="0 0 0" xyz="0 0 0"/>
    <visual>
      <geometry>
        <mesh filename="file:///home/dada/raicam_ws/summit_arm_sim/src/husky_description/meshes/accessories/510_mm_sensor_arch.dae"/>
      </geometry>
    </visual>
    <collision>
      <origin rpy="0 0 0" xyz="0 0 0"/>
      <geometry>
        <mesh filename="file:///home/dada/raicam_ws/summit_arm_sim/src/husky_description/meshes/accessories/510_mm_sensor_arch.dae"/>
      </geometry>
    </collision>
  </link>
  <!-- Attach the sensor arch to the top plate -->
  <joint name="husky_sensor_arch_mount" type="fixed">
    <origin rpy="0 0 -3.14" xyz="-0.35 0 0.51"/>
    <parent link="husky_top_plate_link"/>
    <child link="husky_sensor_arch_mount_link"/>
  </joint>
  <!-- This file is a placeholder which is included by default from
       husky.urdf.xacro. If a robot is being customized and requires
       additional URDF, set the HUSKY_URDF_EXTRAS environment variable
       to the full path of the file you would like included. -->
  <!--
    Base UR robot series xacro macro.

    NOTE this is NOT a URDF. It cannot directly be loaded by consumers
    expecting a flattened '.urdf' file. See the top-level '.xacro' for that
    (but note that .xacro must still be processed by the xacro command).

    This file models the base kinematic chain of a UR robot, which then gets
    parameterised by various configuration files to convert it into a UR3(e),
    UR5(e), UR10(e) or UR16e.

    NOTE the default kinematic parameters (i.e., link lengths, frame locations,
    offsets, etc) do not correspond to any particular robot. They are defaults
    only. There WILL be non-zero offsets between the Forward Kinematics results
    in TF (i.e., robot_state_publisher) and the values reported by the Teach
    Pendant.

    For accurate (and robot-specific) transforms, the 'kinematics_parameters_file'
    parameter MUST point to a .yaml file containing the appropriate values for
    the targeted robot.

    If using the UniversalRobots/Universal_Robots_ROS_Driver, follow the steps
    described in the readme of that repository to extract the kinematic
    calibration from the controller and generate the required .yaml file.

    Main author of the migration to yaml configs Ludovic Delval.

    Contributors to previous versions (in no particular order)

     - Denis Stogl
     - Lovro Ivanov
     - Felix Messmer
     - Kelsey Hawkins
     - Wim Meeussen
     - Shaun Edwards
     - Nadia Hammoudeh Garcia
     - Dave Hershberger
     - G. vd. Hoorn
     - Philip Long
     - Dave Coleman
     - Miguel Prada
     - Mathias Luedtke
     - Marcel Schnirring
     - Felix von Drigalski
     - Felix Exner
     - Jimmy Da Silva
     - Ajit Krisshna N L
     - Muhammad Asif Rana
  -->
  <!--
    NOTE the macro defined in this file is NOT part of the public API of this
          package. Users CANNOT rely on this file being available, or stored in
          this location. Nor can they rely on the existence of the macro.
  -->
  <!-- create link fixed to the "world" -->
  <!-- <link name="world" /> -->
  <!-- ros2 control include -->
  <!-- <xacro:include filename="$(find ur5_isaac_simulation)/urdf/ur.ros2_control.xacro" /> -->
  <!-- ros2 control instance -->
  <!-- <xacro:ur_ros2_control name="${name}" use_fake_hardware="${use_fake_hardware}" initial_positions="${initial_positions}" fake_sensor_commands="${fake_sensor_commands}" headless_mode="${headless_mode}" sim_gazebo="${sim_gazebo}" sim_ignition="${sim_ignition}" script_filename="${script_filename}" output_recipe_filename="${output_recipe_filename}" input_recipe_filename="${input_recipe_filename}" tf_prefix="${tf_prefix}" hash_kinematics="${kinematics_hash}" robot_ip="${robot_ip}" use_tool_communication="${use_tool_communication}" tool_voltage="${tool_voltage}" tool_parity="${tool_parity}" tool_baud_rate="${tool_baud_rate}" tool_stop_bits="${tool_stop_bits}" tool_rx_idle_chars="${tool_rx_idle_chars}" tool_tx_idle_chars="${tool_tx_idle_chars}" tool_device_name="${tool_device_name}" tool_tcp_port="${tool_tcp_port}" reverse_port="${reverse_port}" script_sender_port="${script_sender_port}" reverse_ip="${reverse_ip}" script_command_port="${script_command_port}" trajectory_port="${trajectory_port}" non_blocking_read="${non_blocking_read}" keep_alive_count="${keep_alive_count}" /> -->
  <!-- Add URDF transmission elements (for ros_control) -->
  <!--<xacro:ur_arm_transmission prefix="${prefix}" hw_interface="${transmission_hw_interface}" />-->
  <!-- Placeholder for ros2_control transmission which don't yet exist -->
  <!-- links -  main serial chain -->
  <link name="ur5_base_link"/>
  <link name="ur5_base_link_inertia">
    <visual>
      <origin rpy="0 0 3.141592653589793" xyz="0 0 0"/>
      <geometry>
        <mesh filename="/home/dada/raicam_ws/summit_arm_sim/src/ur5_isaac_simulation/meshes/ur5/visual/base.dae"/>
      </geometry>
    </visual>
    <collision>
      <origin rpy="0 0 3.141592653589793" xyz="0 0 0"/>
      <geometry>
        <mesh filename="/home/dada/raicam_ws/summit_arm_sim/src/ur5_isaac_simulation/meshes/ur5/collision/base.stl"/>
      </geometry>
    </collision>
    <inertial>
      <mass value="4.0"/>
      <origin rpy="0 0 0" xyz="0 0 0"/>
      <inertia ixx="0.00443333156" ixy="0.0" ixz="0.0" iyy="0.00443333156" iyz="0.0" izz="0.0072"/>
    </inertial>
  </link>
  <link name="ur5_shoulder_link">
    <visual>
      <origin rpy="0 0 3.141592653589793" xyz="0 0 0"/>
      <geometry>
        <mesh filename="/home/dada/raicam_ws/summit_arm_sim/src/ur5_isaac_simulation/meshes/ur5/visual/shoulder.dae"/>
      </geometry>
    </visual>
    <collision>
      <origin rpy="0 0 3.141592653589793" xyz="0 0 0"/>
      <geometry>
        <mesh filename="/home/dada/raicam_ws/summit_arm_sim/src/ur5_isaac_simulation/meshes/ur5/collision/shoulder.stl"/>
      </geometry>
    </collision>
    <inertial>
      <mass value="3.7"/>
      <origin rpy="0 0 0" xyz="0 0 0"/>
      <inertia ixx="0.014972352344389999" ixy="0.0" ixz="0.0" iyy="0.014972352344389999" iyz="0.0" izz="0.01040625"/>
    </inertial>
  </link>
  <link name="ur5_upper_arm_link">
    <visual>
      <origin rpy="1.5707963267948966 0 -1.5707963267948966" xyz="0 0 0.13585"/>
      <geometry>
        <mesh filename="/home/dada/raicam_ws/summit_arm_sim/src/ur5_isaac_simulation/meshes/ur5/visual/upperarm.dae"/>
      </geometry>
    </visual>
    <collision>
      <origin rpy="1.5707963267948966 0 -1.5707963267948966" xyz="0 0 0.13585"/>
      <geometry>
        <mesh filename="/home/dada/raicam_ws/summit_arm_sim/src/ur5_isaac_simulation/meshes/ur5/collision/upperarm.stl"/>
      </geometry>
    </collision>
    <inertial>
      <mass value="8.393"/>
      <origin rpy="0 1.5707963267948966 0" xyz="-0.2125 0.0 0.136"/>
      <inertia ixx="0.1338857818623325" ixy="0.0" ixz="0.0" iyy="0.1338857818623325" iyz="0.0" izz="0.0151074"/>
    </inertial>
  </link>
  <link name="ur5_forearm_link">
    <visual>
      <origin rpy="1.5707963267948966 0 -1.5707963267948966" xyz="0 0 0.0165"/>
      <geometry>
        <mesh filename="/home/dada/raicam_ws/summit_arm_sim/src/ur5_isaac_simulation/meshes/ur5/visual/forearm.dae"/>
      </geometry>
    </visual>
    <collision>
      <origin rpy="1.5707963267948966 0 -1.5707963267948966" xyz="0 0 0.0165"/>
      <geometry>
        <mesh filename="/home/dada/raicam_ws/summit_arm_sim/src/ur5_isaac_simulation/meshes/ur5/collision/forearm.stl"/>
      </geometry>
    </collision>
    <inertial>
      <mass value="2.275"/>
      <origin rpy="0 1.5707963267948966 0" xyz="-0.196125 0.0 0.0165"/>
      <inertia ixx="0.03121679102890359" ixy="0.0" ixz="0.0" iyy="0.03121679102890359" iyz="0.0" izz="0.004095"/>
    </inertial>
  </link>
  <link name="ur5_wrist_1_link">
    <visual>
      <origin rpy="1.5707963267948966 0 0" xyz="0 0 -0.093"/>
      <geometry>
        <mesh filename="/home/dada/raicam_ws/summit_arm_sim/src/ur5_isaac_simulation/meshes/ur5/visual/wrist1.dae"/>
      </geometry>
    </visual>
    <collision>
      <origin rpy="1.5707963267948966 0 0" xyz="0 0 -0.093"/>
      <geometry>
        <mesh filename="/home/dada/raicam_ws/summit_arm_sim/src/ur5_isaac_simulation/meshes/ur5/collision/wrist1.stl"/>
      </geometry>
    </collision>
    <inertial>
      <mass value="1.219"/>
      <origin rpy="0 0 0" xyz="0 0 0"/>
      <inertia ixx="0.0020138887777775" ixy="0.0" ixz="0.0" iyy="0.0020138887777775" iyz="0.0" izz="0.0021942"/>
    </inertial>
  </link>
  <link name="ur5_wrist_2_link">
    <visual>
      <origin rpy="0 0 0" xyz="0 0 -0.095"/>
      <geometry>
        <mesh filename="/home/dada/raicam_ws/summit_arm_sim/src/ur5_isaac_simulation/meshes/ur5/visual/wrist2.dae"/>
      </geometry>
    </visual>
    <collision>
      <origin rpy="0 0 0" xyz="0 0 -0.095"/>
      <geometry>
        <mesh filename="/home/dada/raicam_ws/summit_arm_sim/src/ur5_isaac_simulation/meshes/ur5/collision/wrist2.stl"/>
      </geometry>
    </collision>
    <inertial>
      <mass value="1.219"/>
      <origin rpy="0 0 0" xyz="0 0 0"/>
      <inertia ixx="0.0018310388509175" ixy="0.0" ixz="0.0" iyy="0.0018310388509175" iyz="0.0" izz="0.0021942"/>
    </inertial>
  </link>
  <link name="ur5_wrist_3_link">
    <visual>
      <origin rpy="1.5707963267948966 0 0" xyz="0 0 -0.0818"/>
      <geometry>
        <mesh filename="/home/dada/raicam_ws/summit_arm_sim/src/ur5_isaac_simulation/meshes/ur5/visual/wrist3.dae"/>
      </geometry>
    </visual>
    <collision>
      <origin rpy="1.5707963267948966 0 0" xyz="0 0 -0.0818"/>
      <geometry>
        <mesh filename="/home/dada/raicam_ws/summit_arm_sim/src/ur5_isaac_simulation/meshes/ur5/collision/wrist3.stl"/>
      </geometry>
    </collision>
    <inertial>
      <mass value="0.1879"/>
      <origin rpy="0 0 0" xyz="0.0 0.0 -0.01525"/>
      <inertia ixx="8.062472608343e-05" ixy="0.0" ixz="0.0" iyy="8.062472608343e-05" iyz="0.0" izz="0.0001321171875"/>
    </inertial>
  </link>
  <!-- base_joint fixes base_link to the environment -->
  <joint name="ur5_base_joint" type="fixed">
    <origin rpy="0 0 0" xyz="0.25 0 0"/>
    <parent link="husky_top_plate_link"/>
    <child link="ur5_base_link"/>
  </joint>
  <!-- joints - main serial chain -->
  <joint name="ur5_base_link-base_link_inertia" type="fixed">
    <parent link="ur5_base_link"/>
    <child link="ur5_base_link_inertia"/>
    <!-- 'base_link' is REP-103 aligned (so X+ forward), while the internal
           frames of the robot/controller have X+ pointing backwards.
           Use the joint between 'base_link' and 'base_link_inertia' (a dummy
           link/frame) to introduce the necessary rotation over Z (of pi rad).
      -->
    <origin rpy="0 0 3.141592653589793" xyz="0 0 0"/>
  </joint>
  <joint name="ur5_shoulder_pan_joint" type="revolute">
    <parent link="ur5_base_link_inertia"/>
    <child link="ur5_shoulder_link"/>
    <origin rpy="0 0 0" xyz="0 0 0.089159"/>
    <axis xyz="0 0 1"/>
    <limit effort="150.0" lower="-6.283185307179586" upper="6.283185307179586" velocity="3.141592653589793"/>
    <safety_controller k_position="20" k_velocity="0.0" soft_lower_limit="-6.133185307179586" soft_upper_limit="6.133185307179586"/>
    <dynamics damping="0" friction="0"/>
  </joint>
  <joint name="ur5_shoulder_lift_joint" type="revolute">
    <parent link="ur5_shoulder_link"/>
    <child link="ur5_upper_arm_link"/>
    <origin rpy="1.570796327 0 0" xyz="0 0 0"/>
    <axis xyz="0 0 1"/>
    <limit effort="150.0" lower="-6.283185307179586" upper="6.283185307179586" velocity="3.141592653589793"/>
    <safety_controller k_position="20" k_velocity="0.0" soft_lower_limit="-6.133185307179586" soft_upper_limit="6.133185307179586"/>
    <dynamics damping="0" friction="0"/>
  </joint>
  <joint name="ur5_elbow_joint" type="revolute">
    <parent link="ur5_upper_arm_link"/>
    <child link="ur5_forearm_link"/>
    <origin rpy="0 0 0" xyz="-0.425 0 0"/>
    <axis xyz="0 0 1"/>
    <limit effort="150.0" lower="-3.141592653589793" upper="3.141592653589793" velocity="3.141592653589793"/>
    <safety_controller k_position="20" k_velocity="0.0" soft_lower_limit="-2.991592653589793" soft_upper_limit="2.991592653589793"/>
    <dynamics damping="0" friction="0"/>
  </joint>
  <joint name="ur5_wrist_1_joint" type="revolute">
    <parent link="ur5_forearm_link"/>
    <child link="ur5_wrist_1_link"/>
    <origin rpy="0 0 0" xyz="-0.39225 0 0.10915"/>
    <axis xyz="0 0 1"/>
    <limit effort="28.0" lower="-6.283185307179586" upper="6.283185307179586" velocity="3.141592653589793"/>
    <safety_controller k_position="20" k_velocity="0.0" soft_lower_limit="-6.133185307179586" soft_upper_limit="6.133185307179586"/>
    <dynamics damping="0" friction="0"/>
  </joint>
  <joint name="ur5_wrist_2_joint" type="revolute">
    <parent link="ur5_wrist_1_link"/>
    <child link="ur5_wrist_2_link"/>
    <origin rpy="1.570796327 0 0" xyz="0 -0.09465 -1.941303950897609e-11"/>
    <axis xyz="0 0 1"/>
    <limit effort="28.0" lower="-6.283185307179586" upper="6.283185307179586" velocity="3.141592653589793"/>
    <safety_controller k_position="20" k_velocity="0.0" soft_lower_limit="-6.133185307179586" soft_upper_limit="6.133185307179586"/>
    <dynamics damping="0" friction="0"/>
  </joint>
  <joint name="ur5_wrist_3_joint" type="revolute">
    <parent link="ur5_wrist_2_link"/>
    <child link="ur5_wrist_3_link"/>
    <origin rpy="1.570796326589793 3.141592653589793 3.141592653589793" xyz="0 0.0823 -1.688001216681175e-11"/>
    <axis xyz="0 0 1"/>
    <limit effort="28.0" lower="-6.283185307179586" upper="6.283185307179586" velocity="3.141592653589793"/>
    <safety_controller k_position="20" k_velocity="0.0" soft_lower_limit="-6.133185307179586" soft_upper_limit="6.133185307179586"/>
    <dynamics damping="0" friction="0"/>
  </joint>
  <link name="ur5_ft_frame"/>
  <joint name="ur5_wrist_3_link-ft_frame" type="fixed">
    <parent link="ur5_wrist_3_link"/>
    <child link="ur5_ft_frame"/>
    <origin rpy="3.141592653589793 0 0" xyz="0 0 0"/>
  </joint>
  <!-- ROS-Industrial 'base' frame - base_link to UR 'Base' Coordinates transform -->
  <link name="ur5_base"/>
  <joint name="ur5_base_link-base_fixed_joint" type="fixed">
    <!-- Note the rotation over Z of pi radians - as base_link is REP-103
           aligned (i.e., has X+ forward, Y+ left and Z+ up), this is needed
           to correctly align 'base' with the 'Base' coordinate system of
           the UR controller.
      -->
    <origin rpy="0 0 3.141592653589793" xyz="0 0 0"/>
    <parent link="ur5_base_link"/>
    <child link="ur5_base"/>
  </joint>
  <!-- ROS-Industrial 'flange' frame - attachment point for EEF models -->
  <link name="ur5_flange"/>
  <joint name="ur5_wrist_3-flange" type="fixed">
    <parent link="ur5_wrist_3_link"/>
    <child link="ur5_flange"/>
    <origin rpy="0 -1.5707963267948966 -1.5707963267948966" xyz="0 0 0"/>
  </joint>
  <!-- ROS-Industrial 'tool0' frame - all-zeros tool frame -->
  <link name="ur5_tool0"/>
  <joint name="ur5_flange-tool0" type="fixed">
    <!-- default toolframe - X+ left, Y+ up, Z+ front -->
    <origin rpy="1.5707963267948966 0 1.5707963267948966" xyz="0 0 0"/>
    <parent link="ur5_flange"/>
    <child link="ur5_tool0"/>
  </joint>
  <!-- GRIPPER -->
  <link name="robotiq_arg2f_base_link">
    <inertial>
      <origin rpy="0 0 0" xyz="8.625E-08 -4.6583E-06 0.03145"/>
      <mass value="0.22652"/>
      <inertia ixx="0.00020005" ixy="-4.2442E-10" ixz="-2.9069E-10" iyy="0.00017832" iyz="-3.4402E-08" izz="0.00013478"/>
    </inertial>
    <visual>
      <origin rpy="0 0 0" xyz="0 0 0"/>
      <geometry>
        <mesh filename="/home/dada/raicam_ws/summit_arm_sim/src/ur5_isaac_simulation/meshes/robotiq_2f_140/visual/robotiq_arg2f_base_link.stl"/>
      </geometry>
      <material name="">
        <color rgba="0.1 0.1 0.1 1"/>
      </material>
    </visual>
    <collision>
      <origin rpy="0 0 0" xyz="0 0 0"/>
      <geometry>
        <mesh filename="/home/dada/raicam_ws/summit_arm_sim/src/ur5_isaac_simulation/meshes/robotiq_2f_140/collision/robotiq_arg2f_base_link.stl"/>
      </geometry>
    </collision>
  </link>
  <joint name="robotiq_fixed" type="fixed">
    <!-- default toolframe - X+ left, Y+ up, Z+ front -->
    <origin rpy="0 0 0" xyz="0 0 0"/>
    <parent link="ur5_tool0"/>
    <child link="robotiq_arg2f_base_link"/>
  </joint>
  <link name="left_outer_knuckle">
    <inertial>
      <origin rpy="0 0 0" xyz="-0.000200000000003065 0.0199435877845359 0.0292245259211331"/>
      <mass value="0.00853198276973456"/>
      <inertia ixx="2.89328108496468E-06" ixy="-1.57935047237397E-19" ixz="-1.93980378593255E-19" iyy="1.86719750325683E-06" iyz="-1.21858577871576E-06" izz="1.21905238907251E-06"/>
    </inertial>
    <visual>
      <origin rpy="0 0 0" xyz="0 0 0"/>
      <geometry>
        <mesh filename="/home/dada/raicam_ws/summit_arm_sim/src/ur5_isaac_simulation/meshes/robotiq_2f_140/visual/robotiq_arg2f_140_outer_knuckle.stl"/>
      </geometry>
      <material name="">
        <color rgba="0.792156862745098 0.819607843137255 0.933333333333333 1"/>
      </material>
    </visual>
    <collision>
      <origin rpy="0 0 0" xyz="0 0 0"/>
      <geometry>
        <mesh filename="/home/dada/raicam_ws/summit_arm_sim/src/ur5_isaac_simulation/meshes/robotiq_2f_140/collision/robotiq_arg2f_140_outer_knuckle.stl"/>
      </geometry>
    </collision>
  </link>
  <link name="left_outer_finger">
    <inertial>
      <origin rpy="0 0 0" xyz="0.00030115855001899 0.0373907951953854 -0.0208027427000385"/>
      <mass value="0.022614240507152"/>
      <inertia ixx="1.52518312458174E-05" ixy="9.76583423954399E-10" ixz="-5.43838577022588E-10" iyy="6.17694243867776E-06" iyz="6.78636130740228E-06" izz="1.16494917907219E-05"/>
    </inertial>
    <visual>
      <origin rpy="0 0 0" xyz="0 0 0"/>
      <geometry>
        <mesh filename="/home/dada/raicam_ws/summit_arm_sim/src/ur5_isaac_simulation/meshes/robotiq_2f_140/visual/robotiq_arg2f_140_outer_finger.stl"/>
      </geometry>
      <material name="">
        <color rgba="0.1 0.1 0.1 1"/>
      </material>
    </visual>
    <collision>
      <origin rpy="0 0 0" xyz="0 0 0"/>
      <geometry>
        <mesh filename="/home/dada/raicam_ws/summit_arm_sim/src/ur5_isaac_simulation/meshes/robotiq_2f_140/collision/robotiq_arg2f_140_outer_finger.stl"/>
      </geometry>
    </collision>
  </link>
  <link name="left_inner_finger">
    <inertial>
      <origin rpy="0 0 0" xyz="0.000299999999999317 0.0160078233491243 -0.0136945669206257"/>
      <mass value="0.0104003125914103"/>
      <inertia ixx="2.71909453810972E-06" ixy="1.35402465472579E-21" ixz="-7.1817349065269E-22" iyy="7.69100314106116E-07" iyz="6.74715432769696E-07" izz="2.30315190420171E-06"/>
    </inertial>
    <visual>
      <origin rpy="0 0 0" xyz="0 0 0"/>
      <geometry>
        <mesh filename="/home/dada/raicam_ws/summit_arm_sim/src/ur5_isaac_simulation/meshes/robotiq_2f_140/visual/robotiq_arg2f_140_inner_finger.stl"/>
      </geometry>
      <material name="">
        <color rgba="0.1 0.1 0.1 1"/>
      </material>
    </visual>
    <collision>
      <origin rpy="0 0 0" xyz="0 0 0"/>
      <geometry>
        <mesh filename="/home/dada/raicam_ws/summit_arm_sim/src/ur5_isaac_simulation/meshes/robotiq_2f_140/collision/robotiq_arg2f_140_inner_finger.stl"/>
      </geometry>
    </collision>
  </link>
  <link name="left_inner_finger_pad">
    <visual>
      <origin rpy="0 0 0" xyz="0 0 0"/>
      <geometry>
        <box size="0.027 0.065 0.0075"/>
      </geometry>
      <material name="">
        <color rgba="0.9 0.9 0.9 1"/>
      </material>
    </visual>
    <collision>
      <origin rpy="0 0 0" xyz="0 0 0"/>
      <geometry>
        <box size="0.03 0.07 0.0075"/>
      </geometry>
      <material name="">
        <color rgba="0.9 0.0 0.0 1"/>
      </material>
    </collision>
  </link>
  <link name="left_inner_knuckle">
    <inertial>
      <origin rpy="0 0 0" xyz="0.000123011831763771 0.0507850843201817 0.00103968640075166"/>
      <mass value="0.0271177346495152"/>
      <inertia ixx="2.61910379223783E-05" ixy="-2.43616858946494E-07" ixz="-6.37789906117123E-09" iyy="2.8270243746167E-06" iyz="-5.37200748039765E-07" izz="2.83695868220296E-05"/>
    </inertial>
    <visual>
      <origin rpy="0 0 0" xyz="0 0 0"/>
      <geometry>
        <mesh filename="/home/dada/raicam_ws/summit_arm_sim/src/ur5_isaac_simulation/meshes/robotiq_2f_140/visual/robotiq_arg2f_140_inner_knuckle.stl"/>
      </geometry>
      <material name="">
        <color rgba="0.1 0.1 0.1 1"/>
      </material>
    </visual>
    <collision>
      <origin rpy="0 0 0" xyz="0 0 0"/>
      <geometry>
        <mesh filename="/home/dada/raicam_ws/summit_arm_sim/src/ur5_isaac_simulation/meshes/robotiq_2f_140/collision/robotiq_arg2f_140_inner_knuckle.stl"/>
      </geometry>
    </collision>
  </link>
  <link name="right_outer_knuckle">
    <inertial>
      <origin rpy="0 0 0" xyz="-0.000200000000003065 0.0199435877845359 0.0292245259211331"/>
      <mass value="0.00853198276973456"/>
      <inertia ixx="2.89328108496468E-06" ixy="-1.57935047237397E-19" ixz="-1.93980378593255E-19" iyy="1.86719750325683E-06" iyz="-1.21858577871576E-06" izz="1.21905238907251E-06"/>
    </inertial>
    <visual>
      <origin rpy="0 0 0" xyz="0 0 0"/>
      <geometry>
        <mesh filename="/home/dada/raicam_ws/summit_arm_sim/src/ur5_isaac_simulation/meshes/robotiq_2f_140/visual/robotiq_arg2f_140_outer_knuckle.stl"/>
      </geometry>
      <material name="">
        <color rgba="0.792156862745098 0.819607843137255 0.933333333333333 1"/>
      </material>
    </visual>
    <collision>
      <origin rpy="0 0 0" xyz="0 0 0"/>
      <geometry>
        <mesh filename="/home/dada/raicam_ws/summit_arm_sim/src/ur5_isaac_simulation/meshes/robotiq_2f_140/collision/robotiq_arg2f_140_outer_knuckle.stl"/>
      </geometry>
    </collision>
  </link>
  <link name="right_outer_finger">
    <inertial>
      <origin rpy="0 0 0" xyz="0.00030115855001899 0.0373907951953854 -0.0208027427000385"/>
      <mass value="0.022614240507152"/>
      <inertia ixx="1.52518312458174E-05" ixy="9.76583423954399E-10" ixz="-5.43838577022588E-10" iyy="6.17694243867776E-06" iyz="6.78636130740228E-06" izz="1.16494917907219E-05"/>
    </inertial>
    <visual>
      <origin rpy="0 0 0" xyz="0 0 0"/>
      <geometry>
        <mesh filename="/home/dada/raicam_ws/summit_arm_sim/src/ur5_isaac_simulation/meshes/robotiq_2f_140/visual/robotiq_arg2f_140_outer_finger.stl"/>
      </geometry>
      <material name="">
        <color rgba="0.1 0.1 0.1 1"/>
      </material>
    </visual>
    <collision>
      <origin rpy="0 0 0" xyz="0 0 0"/>
      <geometry>
        <mesh filename="/home/dada/raicam_ws/summit_arm_sim/src/ur5_isaac_simulation/meshes/robotiq_2f_140/collision/robotiq_arg2f_140_outer_finger.stl"/>
      </geometry>
    </collision>
  </link>
  <link name="right_inner_finger">
    <inertial>
      <origin rpy="0 0 0" xyz="0.000299999999999317 0.0160078233491243 -0.0136945669206257"/>
      <mass value="0.0104003125914103"/>
      <inertia ixx="2.71909453810972E-06" ixy="1.35402465472579E-21" ixz="-7.1817349065269E-22" iyy="7.69100314106116E-07" iyz="6.74715432769696E-07" izz="2.30315190420171E-06"/>
    </inertial>
    <visual>
      <origin rpy="0 0 0" xyz="0 0 0"/>
      <geometry>
        <mesh filename="/home/dada/raicam_ws/summit_arm_sim/src/ur5_isaac_simulation/meshes/robotiq_2f_140/visual/robotiq_arg2f_140_inner_finger.stl"/>
      </geometry>
      <material name="">
        <color rgba="0.1 0.1 0.1 1"/>
      </material>
    </visual>
    <collision>
      <origin rpy="0 0 0" xyz="0 0 0"/>
      <geometry>
        <mesh filename="/home/dada/raicam_ws/summit_arm_sim/src/ur5_isaac_simulation/meshes/robotiq_2f_140/collision/robotiq_arg2f_140_inner_finger.stl"/>
      </geometry>
    </collision>
  </link>
  <link name="right_inner_finger_pad">
    <visual>
      <origin rpy="0 0 0" xyz="0 0 0"/>
      <geometry>
        <box size="0.027 0.065 0.0075"/>
      </geometry>
      <material name="">
        <color rgba="0.9 0.9 0.9 1"/>
      </material>
    </visual>
    <collision>
      <origin rpy="0 0 0" xyz="0 0 0"/>
      <geometry>
        <box size="0.03 0.07 0.0075"/>
      </geometry>
      <material name="">
        <color rgba="0.9 0.0 0.0 1"/>
      </material>
    </collision>
  </link>
  <link name="right_inner_knuckle">
    <inertial>
      <origin rpy="0 0 0" xyz="0.000123011831763771 0.0507850843201817 0.00103968640075166"/>
      <mass value="0.0271177346495152"/>
      <inertia ixx="2.61910379223783E-05" ixy="-2.43616858946494E-07" ixz="-6.37789906117123E-09" iyy="2.8270243746167E-06" iyz="-5.37200748039765E-07" izz="2.83695868220296E-05"/>
    </inertial>
    <visual>
      <origin rpy="0 0 0" xyz="0 0 0"/>
      <geometry>
        <mesh filename="/home/dada/raicam_ws/summit_arm_sim/src/ur5_isaac_simulation/meshes/robotiq_2f_140/visual/robotiq_arg2f_140_inner_knuckle.stl"/>
      </geometry>
      <material name="">
        <color rgba="0.1 0.1 0.1 1"/>
      </material>
    </visual>
    <collision>
      <origin rpy="0 0 0" xyz="0 0 0"/>
      <geometry>
        <mesh filename="/home/dada/raicam_ws/summit_arm_sim/src/ur5_isaac_simulation/meshes/robotiq_2f_140/collision/robotiq_arg2f_140_inner_knuckle.stl"/>
      </geometry>
    </collision>
  </link>
  <joint name="finger_joint" type="revolute">
    <origin rpy="2.2957963267948966 0 0" xyz="0 -0.030601 0.054905"/>
    <parent link="robotiq_arg2f_base_link"/>
    <child link="left_outer_knuckle"/>
    <axis xyz="-1 0 0"/>
    <limit effort="1000" lower="-0.725" upper="0.725" velocity="2.0"/>
  </joint>
  <joint name="left_outer_finger_joint" type="fixed">
    <origin rpy="0 0 0" xyz="0 0.01821998610742 0.0260018192872234"/>
    <parent link="left_outer_knuckle"/>
    <child link="left_outer_finger"/>
    <axis xyz="1 0 0"/>
  </joint>
  <joint name="left_inner_knuckle_joint" type="revolute">
    <origin rpy="2.2957963267948966 0 0.0" xyz="0 -0.0127 0.06142"/>
    <parent link="robotiq_arg2f_base_link"/>
    <child link="left_inner_knuckle"/>
    <axis xyz="1 0 0"/>
    <limit effort="1000" lower="-0.8757" upper="0.8757" velocity="2.0"/>
    <mimic joint="finger_joint" multiplier="-1" offset="0"/>
  </joint>
  <joint name="left_inner_finger_joint" type="revolute">
    <origin rpy="-0.725 0 0" xyz="0 0.0817554015893473 -0.0282203446692936"/>
    <parent link="left_outer_finger"/>
    <child link="left_inner_finger"/>
    <axis xyz="1 0 0"/>
    <limit effort="1000" lower="-0.8757" upper="0.8757" velocity="2.0"/>
    <mimic joint="finger_joint" multiplier="1" offset="0"/>
  </joint>
  <joint name="left_inner_finger_pad_joint" type="fixed">
    <origin rpy="0 0 0" xyz="0 0.0457554015893473 -0.0272203446692936"/>
    <parent link="left_inner_finger"/>
    <child link="left_inner_finger_pad"/>
    <axis xyz="0 0 1"/>
  </joint>
  <joint name="right_outer_knuckle_joint" type="revolute">
    <origin rpy="2.2957963267948966 0 3.141592653589793" xyz="0 0.030601 0.054905"/>
    <parent link="robotiq_arg2f_base_link"/>
    <child link="right_outer_knuckle"/>
    <axis xyz="1 0 0"/>
    <limit effort="1000" lower="-0.725" upper="0.725" velocity="2.0"/>
    <!-- <mimic joint="finger_joint" multiplier="-1" offset="0"/> -->
  </joint>
  <joint name="right_outer_finger_joint" type="fixed">
    <origin rpy="0 0 0" xyz="0 0.01821998610742 0.0260018192872234"/>
    <parent link="right_outer_knuckle"/>
    <child link="right_outer_finger"/>
    <axis xyz="1 0 0"/>
  </joint>
  <joint name="right_inner_knuckle_joint" type="revolute">
    <origin rpy="2.2957963267948966 0 -3.141592653589793" xyz="0 0.0127 0.06142"/>
    <parent link="robotiq_arg2f_base_link"/>
    <child link="right_inner_knuckle"/>
    <axis xyz="1 0 0"/>
    <limit effort="1000" lower="-0.8757" upper="0.8757" velocity="2.0"/>
    <mimic joint="right_outer_knuckle_joint" multiplier="1" offset="0"/>
  </joint>
  <joint name="right_inner_finger_joint" type="revolute">
    <origin rpy="-0.725 0 0" xyz="0 0.0817554015893473 -0.0282203446692936"/>
    <parent link="right_outer_finger"/>
    <child link="right_inner_finger"/>
    <axis xyz="1 0 0"/>
    <limit effort="1000" lower="-0.8757" upper="0.8757" velocity="2.0"/>
    <mimic joint="right_outer_knuckle_joint" multiplier="-1" offset="0"/>
  </joint>
  <joint name="right_inner_finger_pad_joint" type="fixed">
    <origin rpy="0 0 0" xyz="0 0.0457554015893473 -0.0272203446692936"/>
    <parent link="right_inner_finger"/>
    <child link="right_inner_finger_pad"/>
    <axis xyz="0 0 1"/>
  </joint>
  <transmission name="finger_joint_trans">
    <type>transmission_interface/SimpleTransmission</type>
    <joint name="finger_joint">
      <hardwareInterface>PositionJointInterface</hardwareInterface>
    </joint>
    <actuator name="finger_joint_motor">
      <mechanicalReduction>1</mechanicalReduction>
    </actuator>
  </transmission>
  <!-- 
  <joint name="husky_ur5_joint" type="fixed">
    <origin xyz="0.25 0 0" rpy="0 0 0" />
    <parent link="$(arg prefix)base_link" />
    <child link="${prefix}inertial_link" />
  </joint> -->
</robot>
